Workbook
Name TaxRate: Assumptions!$B$1

Sheet Sales
A1: Region | B1: Product | C1: Units | D1: Unit Price | E1: Discount | F1: Revenue | G1: Tax | H1: Tier | I1: Share | J1: Region Revenue | K1: Region Share | L1: Label | M1: Margin | N1: Code | O1: Region Product Units | P1: List Price | Q1: Running Total
A2: North | B2: Gadget | C2: 25 | D2: 41.81 | F2: =C2*D2*(1-E2) | G2: =F2*TaxRate | H2: =IF(F2>=Assumptions!$B$2,"High",IF(F2>=Assumptions!$B$2/5,"Mid","Low")) | I2: =F2/SUM($F$2:$F$201) | J2: =SUMIF($A$2:$A$201,A2,$F$2:$F$201) | K2: =F2/J2 | L2: =A2&"-"&B2&" x"&C2 | M2: =IFERROR(ROUND((F2-G2)/F2,4),0) | N2: =UPPER(LEFT(B2,3))&MOD(C2,7) | O2: =SUMIFS($C$2:$C$201,$A$2:$A$201,A2,$B$2:$B$201,B2) | P2: =VLOOKUP(B2,Products!$A$2:$B$6,2,FALSE) | Q2: =F2
A3: Central | B3: Widget | C3: 23 | D3: 12.81 | E3: 0.15 | F3: =C3*D3*(1-E3) | G3: =F3*TaxRate | H3: =IF(F3>=Assumptions!$B$2,"High",IF(F3>=Assumptions!$B$2/5,"Mid","Low")) | I3: =F3/SUM($F$2:$F$201) | J3: =SUMIF($A$2:$A$201,A3,$F$2:$F$201) | K3: =F3/J3 | L3: =A3&"-"&B3&" x"&C3 | M3: =IFERROR(ROUND((F3-G3)/F3,4),0) | N3: =UPPER(LEFT(B3,3))&MOD(C3,7) | O3: =SUMIFS($C$2:$C$201,$A$2:$A$201,A3,$B$2:$B$201,B3) | P3: =VLOOKUP(B3,Products!$A$2:$B$6,2,FALSE) | Q3: =Q2+F3
A4: West | B4: Widget | C4: 5 | D4: 12.25 | F4: =C4*D4*(1-E4) | G4: =F4*TaxRate | H4: =IF(F4>=Assumptions!$B$2,"High",IF(F4>=Assumptions!$B$2/5,"Mid","Low")) | I4: =F4/SUM($F$2:$F$201) | J4: =SUMIF($A$2:$A$201,A4,$F$2:$F$201) | K4: =F4/J4 | L4: =A4&"-"&B4&" x"&C4 | M4: =IFERROR(ROUND((F4-G4)/F4,4),0) | N4: =UPPER(LEFT(B4,3))&MOD(C4,7) | O4: =SUMIFS($C$2:$C$201,$A$2:$A$201,A4,$B$2:$B$201,B4) | P4: =VLOOKUP(B4,Products!$A$2:$B$6,2,FALSE) | Q4: =Q3+F4
A5: West | B5: Widget | C5: 35 | D5: 12.22 | E5: 0.15 | F5: =C5*D5*(1-E5) | G5: =F5*TaxRate | H5: =IF(F5>=Assumptions!$B$2,"High",IF(F5>=Assumptions!$B$2/5,"Mid","Low")) | I5: =F5/SUM($F$2:$F$201) | J5: =SUMIF($A$2:$A$201,A5,$F$2:$F$201) | K5: =F5/J5 | L5: =A5&"-"&B5&" x"&C5 | M5: =IFERROR(ROUND((F5-G5)/F5,4),0) | N5: =UPPER(LEFT(B5,3))&MOD(C5,7) | O5: =SUMIFS($C$2:$C$201,$A$2:$A$201,A5,$B$2:$B$201,B5) | P5: =VLOOKUP(B5,Products!$A$2:$B$6,2,FALSE) | Q5: =Q4+F5
A6: East | B6: Gadget | C6: 40 | D6: 41.53 | F6: =C6*D6*(1-E6) | G6: =F6*TaxRate | H6: =IF(F6>=Assumptions!$B$2,"High",IF(F6>=Assumptions!$B$2/5,"Mid","Low")) | I6: =F6/SUM($F$2:$F$201) | J6: =SUMIF($A$2:$A$201,A6,$F$2:$F$201) | K6: =F6/J6 | L6: =A6&"-"&B6&" x"&C6 | M6: =IFERROR(ROUND((F6-G6)/F6,4),0) | N6: =UPPER(LEFT(B6,3))&MOD(C6,7) | O6: =SUMIFS($C$2:$C$201,$A$2:$A$201,A6,$B$2:$B$201,B6) | P6: =VLOOKUP(B6,Products!$A$2:$B$6,2,FALSE) | Q6: =Q5+F6
A7: Central | B7: Sprocket | C7: 25 | D7: 2.68 | E7: 0 | F7: =C7*D7*(1-E7) | G7: =F7*TaxRate | H7: =IF(F7>=Assumptions!$B$2,"High",IF(F7>=Assumptions!$B$2/5,"Mid","Low")) | I7: =F7/SUM($F$2:$F$201) | J7: =SUMIF($A$2:$A$201,A7,$F$2:$F$201) | K7: =F7/J7 | L7: =A7&"-"&B7&" x"&C7 | M7: =IFERROR(ROUND((F7-G7)/F7,4),0) | N7: =UPPER(LEFT(B7,3))&MOD(C7,7) | O7: =SUMIFS($C$2:$C$201,$A$2:$A$201,A7,$B$2:$B$201,B7) | P7: =VLOOKUP(B7,Products!$A$2:$B$6,2,FALSE) | Q7: =Q6+F7
A8: East | B8: Sprocket | C8: 54 | D8: 2.76 | E8: 0.1 | F8: =C8*D8*(1-E8) | G8: =F8*TaxRate | H8: =IF(F8>=Assumptions!$B$2,"High",IF(F8>=Assumptions!$B$2/5,"Mid","Low")) | I8: =F8/SUM($F$2:$F$201) | J8: =SUMIF($A$2:$A$201,A8,$F$2:$F$201) | K8: =F8/J8 | L8: =A8&"-"&B8&" x"&C8 | M8: =IFERROR(ROUND((F8-G8)/F8,4),0) | N8: =UPPER(LEFT(B8,3))&MOD(C8,7) | O8: =SUMIFS($C$2:$C$201,$A$2:$A$201,A8,$B$2:$B$201,B8) | P8: =VLOOKUP(B8,Products!$A$2:$B$6,2,FALSE) | Q8: =Q7+F8
A9: West | B9: Sprocket | C9: 7 | D9: 3.17 | E9: 0.15 | F9: =C9*D9*(1-E9) | G9: 12.5 | H9: =IF(F9>=Assumptions!$B$2,"High",IF(F9>=Assumptions!$B$2/5,"Mid","Low")) | I9: =F9/SUM($F$2:$F$201) | J9: =SUMIF($A$2:$A$201,A9,$F$2:$F$201) | K9: =F9/J9 | L9: =A9&"-"&B9&" x"&C9 | M9: =IFERROR(ROUND((F9-G9)/F9,4),0) | N9: =UPPER(LEFT(B9,3))&MOD(C9,7) | O9: =SUMIFS($C$2:$C$201,$A$2:$A$201,A9,$B$2:$B$201,B9) | P9: =VLOOKUP(B9,Products!$A$2:$B$6,2,FALSE) | Q9: =Q8+F9
A10: West | B10: Widget | C10: 37 | D10: 12.77 | E10: 0 | F10: =C10*D10*(1-E10) | G10: =F10*TaxRate | H10: =IF(F10>=Assumptions!$B$2,"High",IF(F10>=Assumptions!$B$2/5,"Mid","Low")) | I10: =F10/SUM($F$2:$F$201) | J10: =SUMIF($A$2:$A$201,A10,$F$2:$F$201) | K10: =F10/J10 | L10: =A10&"-"&B10&" x"&C10 | M10: =IFERROR(ROUND((F10-G10)/F10,4),0) | N10: =UPPER(LEFT(B10,3))&MOD(C10,7) | O10: =SUMIFS($C$2:$C$201,$A$2:$A$201,A10,$B$2:$B$201,B10) | P10: =VLOOKUP(B10,Products!$A$2:$B$6,2,FALSE) | Q10: =Q9+F10
A11: North | B11: Widget | C11: 35 | D11: 13.3 | E11: 0.15 | F11: =C11*D11*(1-E11) | G11: =F11*TaxRate | H11: =IF(F11>=Assumptions!$B$2,"High",IF(F11>=Assumptions!$B$2/5,"Mid","Low")) | I11: =F11/SUM($F$2:$F$201) | J11: =SUMIF($A$2:$A$201,A11,$F$2:$F$201) | K11: =F11/J11 | L11: =A11&"-"&B11&" x"&C11 | M11: =IFERROR(ROUND((F11-G11)/F11,4),0) | N11: =UPPER(LEFT(B11,3))&MOD(C11,7) | O11: =SUMIFS($C$2:$C$201,$A$2:$A$201,A11,$B$2:$B$201,B11) | P11: =VLOOKUP(B11,Products!$A$2:$B$6,2,FALSE) | Q11: =Q10+F11
A12: East | B12: Sprocket | C12: 13 | D12: 3.1 | E12: 0.15 | F12: =C12*D12*(1-E12) | G12: =F12*TaxRate | H12: =IF(F12>=Assumptions!$B$2,"High",IF(F12>=Assumptions!$B$2/5,"Mid","Low")) | I12: =F12/SUM($F$2:$F$201) | J12: =SUMIF($A$2:$A$201,A12,$F$2:$F$201) | K12: =F12/J12 | L12: =A12&"-"&B12&" x"&C12 | M12: =IFERROR(ROUND((F12-G12)/F12,4),0) | N12: =UPPER(LEFT(B12,3))&MOD(C12,7) | O12: =SUMIFS($C$2:$C$201,$A$2:$A$201,A12,$B$2:$B$201,B12) | P12: =VLOOKUP(B12,Products!$A$2:$B$6,2,FALSE) | Q12: =Q11+F12
A13: South | B13: Gizmo | C13: 29 | D13: 7.44 | E13: 0.1 | F13: =C13*D13*(1-E13) | G13: =F13*TaxRate | H13: =IF(F13>=Assumptions!$B$2,"High",IF(F13>=Assumptions!$B$2/5,"Mid","Low")) | I13: =F13/SUM($F$2:$F$201) | J13: =SUMIF($A$2:$A$201,A13,$F$2:$F$201) | K13: =F13/J13 | L13: =A13&"-"&B13&" x"&C13 | M13: =IFERROR(ROUND((F13-G13)/F13,4),0) | N13: =UPPER(LEFT(B13,3))&MOD(C13,7) | O13: =SUMIFS($C$2:$C$201,$A$2:$A$201,A13,$B$2:$B$201,B13) | P13: =VLOOKUP(B13,Products!$A$2:$B$6,2,FALSE) | Q13: =Q12+F13
A14: North | B14: Gizmo | C14: 15 | D14: 7.89 | E14: 0 | F14: =C14*D14*(1-E14) | G14: =F14*TaxRate | H14: =IF(F14>=Assumptions!$B$2,"High",IF(F14>=Assumptions!$B$2/5,"Mid","Low")) | I14: =F14/SUM($F$2:$F$201) | J14: =SUMIF($A$2:$A$201,A14,$F$2:$F$201) | K14: =F14/J14 | L14: =A14&"-"&B14&" x"&C14 | M14: =IFERROR(ROUND((F14-G14)/F14,4),0) | N14: =UPPER(LEFT(B14,3))&MOD(C14,7) | O14: =SUMIFS($C$2:$C$201,$A$2:$A$201,A14,$B$2:$B$201,B14) | P14: =VLOOKUP(B14,Products!$A$2:$B$6,2,FALSE) | Q14: =Q13+F14
A15: East | B15: Sprocket | C15: 19 | D15: 3.12 | E15: 0.05 | F15: =C15*D15*(1-E15) | G15: =F15*TaxRate | H15: =IF(F15>=Assumptions!$B$2,"High",IF(F15>=Assumptions!$B$2/5,"Mid","Low")) | I15: =F15/SUM($F$2:$F$201) | J15: =SUMIF($A$2:$A$201,A15,$F$2:$F$201) | K15: =F15/J15 | L15: =A15&"-"&B15&" x"&C15 | M15: =IFERROR(ROUND((F15-G15)/F15,4),0) | N15: =UPPER(LEFT(B15,3))&MOD(C15,7) | O15: =SUMIFS($C$2:$C$201,$A$2:$A$201,A15,$B$2:$B$201,B15) | P15: =VLOOKUP(B15,Products!$A$2:$B$6,2,FALSE) | Q15: =Q14+F15
A16: South | B16: Gizmo | C16: 38 | D16: 8.29 | F16: =C16*D16*(1-E16) | G16: =F16*TaxRate | H16: =IF(F16>=Assumptions!$B$2,"High",IF(F16>=Assumptions!$B$2/5,"Mid","Low")) | I16: =F16/SUM($F$2:$F$201) | J16: =SUMIF($A$2:$A$201,A16,$F$2:$F$201) | K16: =F16/J16 | L16: =A16&"-"&B16&" x"&C16 | M16: =IFERROR(ROUND((F16-G16)/F16,4),0) | N16: =UPPER(LEFT(B16,3))&MOD(C16,7) | O16: =SUMIFS($C$2:$C$201,$A$2:$A$201,A16,$B$2:$B$201,B16) | P16: =VLOOKUP(B16,Products!$A$2:$B$6,2,FALSE) | Q16: =Q15+F16
A17: Central | B17: Doohickey | C17: 10 | D17: 106.64 | E17: 0 | F17: =C17*D17*(1-E17) | G17: =F17*TaxRate | H17: =IF(F17>=Assumptions!$B$2,"High",IF(F17>=Assumptions!$B$2/5,"Mid","Low")) | I17: =F17/SUM($F$2:$F$201) | J17: =SUMIF($A$2:$A$201,A17,$F$2:$F$201) | K17: =F17/J17 | L17: =A17&"-"&B17&" x"&C17 | M17: =IFERROR(ROUND((F17-G17)/F17,4),0) | N17: =UPPER(LEFT(B17,3))&MOD(C17,7) | O17: =SUMIFS($C$2:$C$201,$A$2:$A$201,A17,$B$2:$B$201,B17) | P17: =VLOOKUP(B17,Products!$A$2:$B$6,2,FALSE) | Q17: =Q16+F17
A18: South | B18: Doohickey | C18: 2 | D18: 112.72 | F18: =C18*D18*(1-E18) | G18: =F18*TaxRate | H18: =IF(F18>=Assumptions!$B$2,"High",IF(F18>=Assumptions!$B$2/5,"Mid","Low")) | I18: =F18/SUM($F$2:$F$201) | J18: =SUMIF($A$2:$A$201,A18,$F$2:$F$201) | K18: =F18/J18 | L18: =A18&"-"&B18&" x"&C18 | M18: =IFERROR(ROUND((F18-G18)/F18,4),0) | N18: =UPPER(LEFT(B18,3))&MOD(C18,7) | O18: =SUMIFS($C$2:$C$201,$A$2:$A$201,A18,$B$2:$B$201,B18) | P18: =VLOOKUP(B18,Products!$A$2:$B$6,2,FALSE) | Q18: =Q17+F18
A19: Central | B19: Sprocket | C19: 50 | D19: 3.45 | E19: 0.05 | F19: =C19*D19*(1-E19) | G19: =F19*TaxRate | H19: =IF(F19>=Assumptions!$B$2,"High",IF(F19>=Assumptions!$B$2/5,"Mid","Low")) | I19: =F19/SUM($F$2:$F$201) | J19: =SUMIF($A$2:$A$201,A19,$F$2:$F$201) | K19: =F19/J19 | L19: =A19&"-"&B19&" x"&C19 | M19: =IFERROR(ROUND((F19-G19)/F19,4),0) | N19: =UPPER(LEFT(B19,3))&MOD(C19,7) | O19: =SUMIFS($C$2:$C$201,$A$2:$A$201,A19,$B$2:$B$201,B19) | P19: =VLOOKUP(B19,Products!$A$2:$B$6,2,FALSE) | Q19: =Q18+F19
A20: North | B20: Gizmo | C20: 38 | D20: 7.24 | E20: 0.1 | F20: =C20*D20*(1-E20) | G20: =F20*TaxRate | H20: =IF(F20>=Assumptions!$B$2,"High",IF(F20>=Assumptions!$B$2/5,"Mid","Low")) | I20: =F20/SUM($F$2:$F$201) | J20: =SUMIF($A$2:$A$201,A20,$F$2:$F$201) | K20: =F20/J20 | L20: =A20&"-"&B20&" x"&C20 | M20: =IFERROR(ROUND((F20-G20)/F20,4),0) | N20: =UPPER(LEFT(B20,3))&MOD(C20,7) | O20: =SUMIFS($C$2:$C$201,$A$2:$A$201,A20,$B$2:$B$201,B20) | P20: =VLOOKUP(B20,Products!$A$2:$B$6,2,FALSE) | Q20: =Q19+F20
A21: East | B21: Widget | C21: 60 | D21: 11.64 | F21: =C21*D21*(1-E21) | G21: =F21*TaxRate | H21: =IF(F21>=Assumptions!$B$2,"High",IF(F21>=Assumptions!$B$2/5,"Mid","Low")) | I21: =F21/SUM($F$2:$F$201) | J21: =SUMIF($A$2:$A$201,A21,$F$2:$F$201) | K21: =F21/J21 | L21: =A21&"-"&B21&" x"&C21 | M21: =IFERROR(ROUND((F21-G21)/F21,4),0) | N21: =UPPER(LEFT(B21,3))&MOD(C21,7) | O21: =SUMIFS($C$2:$C$201,$A$2:$A$201,A21,$B$2:$B$201,B21) | P21: =VLOOKUP(B21,Products!$A$2:$B$6,2,FALSE) | Q21: =Q20+F21
A22: East | B22: Gizmo | C22: 41 | D22: 7.42 | E22: 0.1 | F22: =C22*D22*(1-E22) | G22: =F22*TaxRate | H22: =IF(F22>=Assumptions!$B$2,"High",IF(F22>=Assumptions!$B$2/5,"Mid","Low")) | I22: =F22/SUM($F$2:$F$201) | J22: =SUMIF($A$2:$A$201,A22,$F$2:$F$201) | K22: =F22/J22 | L22: =A22&"-"&B22&" x"&C22 | M22: =IFERROR(ROUND((F22-G22)/F22,4),0) | N22: =UPPER(LEFT(B22,3))&MOD(C22,7) | O22: =SUMIFS($C$2:$C$201,$A$2:$A$201,A22,$B$2:$B$201,B22) | P22: =VLOOKUP(B22,Products!$A$2:$B$6,2,FALSE) | Q22: =Q21+F22
A23: North | B23: Doohickey | C23: 56 | D23: 104.01 | F23: =C23*D23*(1-E23) | G23: =F23*TaxRate | H23: =IF(F23>=Assumptions!$B$2,"High",IF(F23>=Assumptions!$B$2/5,"Mid","Low")) | I23: =F23/SUM($F$2:$F$201) | J23: =SUMIF($A$2:$A$201,A23,$F$2:$F$201) | K23: =F23/J23 | L23: =A23&"-"&B23&" x"&C23 | M23: =IFERROR(ROUND((F23-G23)/F23,4),0) | N23: =UPPER(LEFT(B23,3))&MOD(C23,7) | O23: =SUMIFS($C$2:$C$201,$A$2:$A$201,A23,$B$2:$B$201,B23) | P23: =VLOOKUP(B23,Products!$A$2:$B$6,2,FALSE) | Q23: =Q22+F23
A24: South | B24: Gizmo | C24: 10 | D24: 7.49 | E24: 0.1 | F24: =C24*D24*(1-E24) | G24: =F24*TaxRate | H24: =IF(F24>=Assumptions!$B$2,"High",IF(F24>=Assumptions!$B$2/5,"Mid","Low")) | I24: =F24/SUM($F$2:$F$201) | J24: =SUMIF($A$2:$A$201,A24,$F$2:$F$201) | K24: =F24/J24 | L24: =A24&"-"&B24&" x"&C24 | M24: =IFERROR(ROUND((F24-G24)/F24,4),0) | N24: =UPPER(LEFT(B24,3))&MOD(C24,7) | O24: =SUMIFS($C$2:$C$201,$A$2:$A$201,A24,$B$2:$B$201,B24) | P24: =VLOOKUP(B24,Products!$A$2:$B$6,2,FALSE) | Q24: =Q23+F24
A25: East | B25: Gadget | C25: 49 | D25: 37.45 | E25: 0 | F25: =C25*D25*(1-E25) | G25: =F25*TaxRate | H25: =IF(F25>=Assumptions!$B$2,"High",IF(F25>=Assumptions!$B$2/5,"Mid","Low")) | I25: =F25/SUM($F$2:$F$201) | J25: =SUMIF($A$2:$A$201,A25,$F$2:$F$201) | K25: =F25/J25 | L25: =A25&"-"&B25&" x"&C25 | M25: =IFERROR(ROUND((F25-G25)/F25,4),0) | N25: =UPPER(LEFT(B25,3))&MOD(C25,7) | O25: =SUMIFS($C$2:$C$201,$A$2:$A$201,A25,$B$2:$B$201,B25) | P25: =VLOOKUP(B25,Products!$A$2:$B$6,2,FALSE) | Q25: =Q24+F25
A26: South | B26: Doohickey | C26: 58 | D26: 110.03 | F26: =C26*D26*(1-E26) | G26: =F26*TaxRate | H26: =IF(F26>=Assumptions!$B$2,"High",IF(F26>=Assumptions!$B$2/5,"Mid","Low")) | I26: =F26/SUM($F$2:$F$201) | J26: =SUMIF($A$2:$A$201,A26,$F$2:$F$201) | K26: =F26/J26 | L26: =A26&"-"&B26&" x"&C26 | M26: =IFERROR(ROUND((F26-G26)/F26,4),0) | N26: =UPPER(LEFT(B26,3))&MOD(C26,7) | O26: =SUMIFS($C$2:$C$201,$A$2:$A$201,A26,$B$2:$B$201,B26) | P26: =VLOOKUP(B26,Products!$A$2:$B$6,2,FALSE) | Q26: =Q25+F26
A27: West | B27: Doohickey | C27: 25 | D27: 100.47 | E27: 0 | F27: =C27*D27*(1-E27) | G27: =F27*TaxRate | H27: =IF(F27>=Assumptions!$B$2,"High",IF(F27>=Assumptions!$B$2/5,"Mid","Low")) | I27: =F27/SUM($F$2:$F$201) | J27: =SUMIF($A$2:$A$201,A27,$F$2:$F$201) | K27: =F27/J27 | L27: =A27&"-"&B27&" x"&C27 | M27: =IFERROR(ROUND((F27-G27)/F27,4),0) | N27: =UPPER(LEFT(B27,3))&MOD(C27,7) | O27: =SUMIFS($C$2:$C$201,$A$2:$A$201,A27,$B$2:$B$201,B27) | P27: =VLOOKUP(B27,Products!$A$2:$B$6,2,FALSE) | Q27: =Q26+F27
A28: South | B28: Sprocket | C28: 17 | D28: 3.29 | E28: 0.05 | F28: =C28*D28*(1-E28) | G28: =F28*TaxRate | H28: =IF(F28>=Assumptions!$B$2,"High",IF(F28>=Assumptions!$B$2/5,"Mid","Low")) | I28: =F28/SUM($F$2:$F$201) | J28: =SUMIF($A$2:$A$201,A28,$F$2:$F$201) | K28: =F28/J28 | L28: =A28&"-"&B28&" x"&C28 | M28: =IFERROR(ROUND((F28-G28)/F28,4),0) | N28: =UPPER(LEFT(B28,3))&MOD(C28,7) | O28: =SUMIFS($C$2:$C$201,$A$2:$A$201,A28,$B$2:$B$201,B28) | P28: =VLOOKUP(B28,Products!$A$2:$B$6,2,FALSE) | Q28: =Q27+F28
A29: South | B29: Gadget | C29: 9 | D29: 35 | E29: 0 | F29: =C29*D29*(1-E29) | G29: =F29*TaxRate | H29: =IF(F29>=Assumptions!$B$2,"High",IF(F29>=Assumptions!$B$2/5,"Mid","Low")) | I29: =F29/SUM($F$2:$F$201) | J29: =SUMIF($A$2:$A$201,A29,$F$2:$F$201) | K29: =F29/J29 | L29: =A29&"-"&B29&" x"&C29 | M29: =IFERROR(ROUND((F29-G29)/F29,4),0) | N29: =UPPER(LEFT(B29,3))&MOD(C29,7) | O29: =SUMIFS($C$2:$C$201,$A$2:$A$201,A29,$B$2:$B$201,B29) | P29: =VLOOKUP(B29,Products!$A$2:$B$6,2,FALSE) | Q29: =Q28+F29
A30: West | B30: Gadget | C30: 0 | D30: 39.82 | E30: 0.15 | F30: =C30*D30*(1-E30) | G30: =F30*TaxRate | H30: =IF(F30>=Assumptions!$B$2,"High",IF(F30>=Assumptions!$B$2/5,"Mid","Low")) | I30: =F30/SUM($F$2:$F$201) | J30: =SUMIF($A$2:$A$201,A30,$F$2:$F$201) | K30: =F30/J30 | L30: =A30&"-"&B30&" x"&C30 | M30: =IFERROR(ROUND((F30-G30)/F30,4),0) | N30: =UPPER(LEFT(B30,3))&MOD(C30,7) | O30: =SUMIFS($C$2:$C$201,$A$2:$A$201,A30,$B$2:$B$201,B30) | P30: =VLOOKUP(B30,Products!$A$2:$B$6,2,FALSE) | Q30: =Q29+F30
A31: West | B31: Gizmo | C31: 18 | D31: 6.17 | E31: 0.1 | F31: =C31*D31*(1-E31) | G31: =F31*TaxRate | H31: =IF(F31>=Assumptions!$B$2,"High",IF(F31>=Assumptions!$B$2/5,"Mid","Low")) | I31: =F31/SUM($F$2:$F$201) | J31: =SUMIF($A$2:$A$201,A31,$F$2:$F$201) | K31: =F31/J31 | L31: =A31&"-"&B31&" x"&C31 | M31: =IFERROR(ROUND((F31-G31)/F31,4),0) | N31: =UPPER(LEFT(B31,3))&MOD(C31,7) | O31: =SUMIFS($C$2:$C$201,$A$2:$A$201,A31,$B$2:$B$201,B31) | P31: =VLOOKUP(B31,Products!$A$2:$B$6,2,FALSE) | Q31: =Q30+F31
A32: Central | B32: Gizmo | C32: 39 | D32: 7.39 | E32: 0 | F32: =C32*D32*(1-E32) | G32: =F32*TaxRate | H32: =IF(F32>=Assumptions!$B$2,"High",IF(F32>=Assumptions!$B$2/5,"Mid","Low")) | I32: =F32/SUM($F$2:$F$201) | J32: =SUMIF($A$2:$A$201,A32,$F$2:$F$201) | K32: =F32/J32 | L32: =A32&"-"&B32&" x"&C32 | M32: =IFERROR(ROUND((F32-G32)/F32,4),0) | N32: =UPPER(LEFT(B32,3))&MOD(C32,7) | O32: =SUMIFS($C$2:$C$201,$A$2:$A$201,A32,$B$2:$B$201,B32) | P32: =VLOOKUP(B32,Products!$A$2:$B$6,2,FALSE) | Q32: =Q31+F32
A33: Central | B33: Sprocket | C33: 41 | D33: 3.26 | F33: =C33*D33*(1-E33) | G33: =F33*TaxRate | H33: =IF(F33>=Assumptions!$B$2,"High",IF(F33>=Assumptions!$B$2/5,"Mid","Low")) | I33: =F33/SUM($F$2:$F$201) | J33: =SUMIF($A$2:$A$201,A33,$F$2:$F$201) | K33: =F33/J33 | L33: =A33&"-"&B33&" x"&C33 | M33: =IFERROR(ROUND((F33-G33)/F33,4),0) | N33: =UPPER(LEFT(B33,3))&MOD(C33,7) | O33: =SUMIFS($C$2:$C$201,$A$2:$A$201,A33,$B$2:$B$201,B33) | P33: =VLOOKUP(B33,Products!$A$2:$B$6,2,FALSE) | Q33: =Q32+F33
A34: South | B34: Sprocket | C34: 25 | D34: 3.01 | E34: 0.1 | F34: =C34*D34*(1-E34) | G34: =F34*TaxRate | H34: =IF(F34>=Assumptions!$B$2,"High",IF(F34>=Assumptions!$B$2/5,"Mid","Low")) | I34: =F34/SUM($F$2:$F$201) | J34: =SUMIF($A$2:$A$201,A34,$F$2:$F$201) | K34: =F34/J34 | L34: =A34&"-"&B34&" x"&C34 | M34: =IFERROR(ROUND((F34-G34)/F34,4),0) | N34: =UPPER(LEFT(B34,3))&MOD(C34,7) | O34: =SUMIFS($C$2:$C$201,$A$2:$A$201,A34,$B$2:$B$201,B34) | P34: =VLOOKUP(B34,Products!$A$2:$B$6,2,FALSE) | Q34: =Q33+F34
A35: East | B35: Doohickey | C35: 40 | D35: 96.04 | E35: 0 | F35: =C35*D35*(1-E35) | G35: =F35*TaxRate | H35: =IF(F35>=Assumptions!$B$2,"High",IF(F35>=Assumptions!$B$2/5,"Mid","Low")) | I35: =F35/SUM($F$2:$F$201) | J35: =SUMIF($A$2:$A$201,A35,$F$2:$F$201) | K35: =F35/J35 | L35: =A35&"-"&B35&" x"&C35 | M35: =IFERROR(ROUND((F35-G35)/F35,4),0) | N35: =UPPER(LEFT(B35,3))&MOD(C35,7) | O35: =SUMIFS($C$2:$C$201,$A$2:$A$201,A35,$B$2:$B$201,B35) | P35: =VLOOKUP(B35,Products!$A$2:$B$6,2,FALSE) | Q35: =Q34+F35
A36: East | B36: Gadget | C36: 28 | D36: 35.95 | E36: 0.05 | F36: =C36*D36*(1-E36) | G36: =F36*TaxRate | H36: =IF(F36>=Assumptions!$B$2,"High",IF(F36>=Assumptions!$B$2/5,"Mid","Low")) | I36: =F36/SUM($F$2:$F$201) | J36: =SUMIF($A$2:$A$201,A36,$F$2:$F$201) | K36: =F36/J36 | L36: =A36&"-"&B36&" x"&C36 | M36: =IFERROR(ROUND((F36-G36)/F36,4),0) | N36: =UPPER(LEFT(B36,3))&MOD(C36,7) | O36: =SUMIFS($C$2:$C$201,$A$2:$A$201,A36,$B$2:$B$201,B36) | P36: =VLOOKUP(B36,Products!$A$2:$B$6,2,FALSE) | Q36: =Q35+F36
A37: Central | B37: Widget | C37: 6 | D37: 10.63 | E37: 0 | F37: =C37*D37*(1-E37) | G37: =F37*TaxRate | H37: =IF(F37>=Assumptions!$B$2,"High",IF(F37>=Assumptions!$B$2/5,"Mid","Low")) | I37: =F37/SUM($F$2:$F$201) | J37: =SUMIF($A$2:$A$201,A37,$F$2:$F$201) | K37: =F37/J37 | L37: =A37&"-"&B37&" x"&C37 | M37: =IFERROR(ROUND((F37-G37)/F37,4),0) | N37: =UPPER(LEFT(B37,3))&MOD(C37,7) | O37: =SUMIFS($C$2:$C$201,$A$2:$A$201,A37,$B$2:$B$201,B37) | P37: =VLOOKUP(B37,Products!$A$2:$B$6,2,FALSE) | Q37: =Q36+F37
A38: Central | B38: Widget | C38: 60 | D38: 11.99 | F38: =C38*D38*(1-E38) | G38: =F38*TaxRate | H38: =IF(F38>=Assumptions!$B$2,"High",IF(F38>=Assumptions!$B$2/5,"Mid","Low")) | I38: =F38/SUM($F$2:$F$201) | J38: =SUMIF($A$2:$A$201,A38,$F$2:$F$201) | K38: =F38/J38 | L38: =A38&"-"&B38&" x"&C38 | M38: =IFERROR(ROUND((F38-G38)/F38,4),0) | N38: =UPPER(LEFT(B38,3))&MOD(C38,7) | O38: =SUMIFS($C$2:$C$201,$A$2:$A$201,A38,$B$2:$B$201,B38) | P38: =VLOOKUP(B38,Products!$A$2:$B$6,2,FALSE) | Q38: =Q37+F38
A39: East | B39: Gadget | C39: 39 | D39: 38.51 | E39: 0.05 | F39: =C39*D39*(1-E39) | G39: =F39*TaxRate | H39: =IF(F39>=Assumptions!$B$2,"High",IF(F39>=Assumptions!$B$2/5,"Mid","Low")) | I39: =F39/SUM($F$2:$F$201) | J39: =SUMIF($A$2:$A$201,A39,$F$2:$F$201) | K39: =F39/J39 | L39: =A39&"-"&B39&" x"&C39 | M39: =IFERROR(ROUND((F39-G39)/F39,4),0) | N39: =UPPER(LEFT(B39,3))&MOD(C39,7) | O39: =SUMIFS($C$2:$C$201,$A$2:$A$201,A39,$B$2:$B$201,B39) | P39: =VLOOKUP(B39,Products!$A$2:$B$6,2,FALSE) | Q39: =Q38+F39
A40: North | B40: Sprocket | C40: 23 | D40: 3.08 | F40: =C40*D40*(1-E40) | G40: =F40*TaxRate | H40: =IF(F40>=Assumptions!$B$2,"High",IF(F40>=Assumptions!$B$2/5,"Mid","Low")) | I40: =F40/SUM($F$2:$F$201) | J40: =SUMIF($A$2:$A$201,A40,$F$2:$F$201) | K40: =F40/J40 | L40: =A40&"-"&B40&" x"&C40 | M40: =IFERROR(ROUND((F40-G40)/F40,4),0) | N40: =UPPER(LEFT(B40,3))&MOD(C40,7) | O40: =SUMIFS($C$2:$C$201,$A$2:$A$201,A40,$B$2:$B$201,B40) | P40: =VLOOKUP(B40,Products!$A$2:$B$6,2,FALSE) | Q40: =Q39+F40
...

Sheet Products
A1: Product | B1: List Price
A2: Widget | B2: 12.5
A3: Gadget | B3: 40
A4: Gizmo | B4: 7.25
A5: Doohickey | B5: 99
A6: Sprocket | B6: 3.1

Sheet Assumptions
A1: Tax Rate | B1: 0.0825
A2: High Threshold | B2: 1000
